<?xml version="1.0" ?>
<robot name="button">

  <material name="red">
    <color rgba="1 0 0 1"/>
  </material>
  <material name="peach">
    <color rgba="0.9 0.75 0.65 1"/>
  </material>

  <link name="button_base">
    <inertial>
      <origin rpy="0 0 0" xyz="0 0 0"/>
      <mass value="0.3"/>
      <inertia ixx="0.0001" ixy="0" ixz="0" iyy="0.0001" iyz="0" izz="0.0001"/>
    </inertial>
    <visual>
      <origin rpy="0 0 0" xyz="0 0 0.0"/>
      <geometry>
        <mesh filename="button_base.obj" scale="0.015 0.015 0.01"/>
      </geometry>
      <material name="peach_base">
        <color rgba="0.9 0.75 0.65 1"/>
      </material>
    </visual>
    <collision>
      <origin rpy="0 0 0" xyz="0 0 0.0"/>
      <geometry>
        <mesh filename="button_base.obj" scale="0.02 0.02 0.01"/>
      </geometry>
    </collision>
  </link>

  <joint name="base_to_head_joint" type="prismatic">
    <parent link="button_base"/>
    <child link="button_head"/>
    <origin xyz="0 0 0.02" rpy="0 0 0"/>
    <axis rpy="0 0 0" xyz="0 0 1"/>
    <limit effort="100" velocity="100" lower="0.0" upper="0.03" />
  </joint>

  <link name="button_head">
    <inertial>
      <origin rpy="0 0 0" xyz="0 0 0"/>
      <mass value="0.1"/>
      <inertia ixx="0.0001" ixy="0" ixz="0" iyy="0.0001" iyz="0" izz="0.0001"/>
    </inertial>
    <visual>
      <origin rpy="0 0 0" xyz="0 0 0"/>
      <geometry>
        <cylinder length="0.04" radius="0.01"/>
      </geometry>
      <material name="red"/>
    </visual>
    <collision>
      <origin rpy="0 0 0" xyz="0 0 0"/>
      <geometry>
        <cylinder length="0.04" radius="0.01"/>
      </geometry>
      <material name="red"/>
    </collision>
  </link>

</robot>