<?xml version="1.0" ?>

<robot name="ur5robot_gripper">
  <!--################################################
  ########              arm                    #######
  ####################################################-->

  <link name="base_link">
    <visual>
      <geometry>
        <mesh filename="../meshes/ur5/visual/base.obj"/>
      </geometry>
      <material name="LightGrey">
        <color rgba="0.7 0.7 0.7 1.0"/>
      </material>
    </visual>
    <collision>
      <geometry>
        <mesh filename="../meshes/ur5/collision/base.stl"/>
      </geometry>
    </collision>
    <inertial>
      <mass value="4.0"/>
      <origin rpy="0 0 0" xyz="0.0 0.0 0.0"/>
      <inertia ixx="0.00443333156" ixy="0.0" ixz="0.0" iyy="0.00443333156" iyz="0.0" izz="0.0072"/>
    </inertial>
  </link>

  <joint name="shoulder_pan_joint" type="revolute">
    <parent link="base_link"/>
    <child link="shoulder_link"/>
    <origin rpy="0.0 0.0 0.0" xyz="0.0 0.0 0.089159"/>
    <axis xyz="0 0 1"/>
    <limit effort="150.0" lower="-6.28318530718" upper="6.28318530718" velocity="3.15"/>
    <dynamics damping="0.0" friction="0.0"/>
  </joint>


  <link name="shoulder_link">
    <visual>
      <geometry>
        <mesh filename="../meshes/ur5/visual/shoulder.obj"/>
      </geometry>
      <material name="LightGrey">
        <color rgba="0.7 0.7 0.7 1.0"/>
      </material>
    </visual>
    <collision>
      <geometry>
        <mesh filename="../meshes/ur5/collision/shoulder.stl"/>
      </geometry>
    </collision>
    <inertial>
      <mass value="3.7"/>
      <origin rpy="0 0 0" xyz="0.0 0.0 0.0"/>
      <inertia ixx="0.010267495893" ixy="0.0" ixz="0.0" iyy="0.010267495893" iyz="0.0" izz="0.00666"/>
    </inertial>
  </link>
  <joint name="shoulder_lift_joint" type="revolute">
    <parent link="shoulder_link"/>
    <child link="upper_arm_link"/>
    <origin rpy="0.0 1.57079632679 0.0" xyz="0.0 0.13585 0.0"/>
    <axis xyz="0 1 0"/>
    <limit effort="150.0" lower="-6.28318530718" upper="6.28318530718" velocity="3.15"/>
    <dynamics damping="0.0" friction="0.0"/>
  </joint>
  <link name="upper_arm_link">
    <visual>
      <geometry>
        <mesh filename="../meshes/ur5/visual/upperarm.obj"/>
      </geometry>
      <material name="LightGrey">
        <color rgba="0.7 0.7 0.7 1.0"/>
      </material>
    </visual>
    <collision>
      <geometry>
        <mesh filename="../meshes/ur5/collision/upperarm.stl"/>
      </geometry>
    </collision>
    <inertial>
      <mass value="8.393"/>
      <origin rpy="0 0 0" xyz="0.0 0.0 0.28"/>
      <inertia ixx="0.22689067591" ixy="0.0" ixz="0.0" iyy="0.22689067591" iyz="0.0" izz="0.0151074"/>
    </inertial>
  </link>
  <joint name="elbow_joint" type="revolute">
    <parent link="upper_arm_link"/>
    <child link="forearm_link"/>
    <origin rpy="0.0 0.0 0.0" xyz="0.0 -0.1197 0.425"/>
    <axis xyz="0 1 0"/>
    <limit effort="150.0" lower="-3.14159265359" upper="3.14159265359" velocity="3.15"/>
    <dynamics damping="0.0" friction="0.0"/>
  </joint>
  <link name="forearm_link">
    <visual>
      <geometry>
        <mesh filename="../meshes/ur5/visual/forearm.obj"/>
      </geometry>
      <material name="LightGrey">
        <color rgba="0.7 0.7 0.7 1.0"/>
      </material>
    </visual>
    <collision>
      <geometry>
        <mesh filename="../meshes/ur5/collision/forearm.stl"/>
      </geometry>
    </collision>
    <inertial>
      <mass value="2.275"/>
      <origin rpy="0 0 0" xyz="0.0 0.0 0.25"/>
      <inertia ixx="0.049443313556" ixy="0.0" ixz="0.0" iyy="0.049443313556" iyz="0.0" izz="0.004095"/>
    </inertial>
  </link>
  <joint name="wrist_1_joint" type="revolute">
    <parent link="forearm_link"/>
    <child link="wrist_1_link"/>
    <origin rpy="0.0 1.57079632679 0.0" xyz="0.0 0.0 0.39225"/>
    <axis xyz="0 1 0"/>
    <limit effort="28.0" lower="-6.28318530718" upper="6.28318530718" velocity="3.2"/>
    <dynamics damping="0.0" friction="0.0"/>
  </joint>
  <link name="wrist_1_link">
    <visual>
      <geometry>
        <mesh filename="../meshes/ur5/visual/wrist1.obj"/>
      </geometry>
      <material name="LightGrey">
        <color rgba="0.7 0.7 0.7 1.0"/>
      </material>
    </visual>
    <collision>
      <geometry>
        <mesh filename="../meshes/ur5/collision/wrist1.stl"/>
      </geometry>
    </collision>
    <inertial>
      <mass value="1.219"/>
      <origin rpy="0 0 0" xyz="0.0 0.0 0.0"/>
      <inertia ixx="0.111172755531" ixy="0.0" ixz="0.0" iyy="0.111172755531" iyz="0.0" izz="0.21942"/>
    </inertial>
  </link>
  <joint name="wrist_2_joint" type="revolute">
    <parent link="wrist_1_link"/>
    <child link="wrist_2_link"/>
    <origin rpy="0.0 0.0 0.0" xyz="0.0 0.093 0.0"/>
    <axis xyz="0 0 1"/>
    <limit effort="28.0" lower="-6.28318530718" upper="6.28318530718" velocity="3.2"/>
    <dynamics damping="0.0" friction="0.0"/>
  </joint>
  <link name="wrist_2_link">
    <visual>
      <geometry>
        <mesh filename="../meshes/ur5/visual/wrist2.obj"/>
      </geometry>
      <material name="LightGrey">
        <color rgba="0.7 0.7 0.7 1.0"/>
      </material>
    </visual>
    <collision>
      <geometry>
        <mesh filename="../meshes/ur5/collision/wrist2.stl"/>
      </geometry>
    </collision>
    <inertial>
      <mass value="1.219"/>
      <origin rpy="0 0 0" xyz="0.0 0.0 0.0"/>
      <inertia ixx="0.111172755531" ixy="0.0" ixz="0.0" iyy="0.111172755531" iyz="0.0" izz="0.21942"/>
    </inertial>
  </link>
  <joint name="wrist_3_joint" type="revolute">
    <parent link="wrist_2_link"/>
    <child link="wrist_3_link"/>
    <origin rpy="0.0 0.0 0.0" xyz="0.0 0.0 0.09465"/>
    <axis xyz="0 1 0"/>
    <limit effort="28.0" lower="-6.28318530718" upper="6.28318530718" velocity="3.2"/>
    <dynamics damping="0.0" friction="0.0"/>
  </joint>
  <link name="wrist_3_link">
    <visual>
      <geometry>
        <mesh filename="../meshes/ur5/visual/wrist3.obj"/>
      </geometry>
      <material name="LightGrey">
        <color rgba="0.7 0.7 0.7 1.0"/>
      </material>
    </visual>
    <collision>
      <geometry>
        <mesh filename="../meshes/ur5/collision/wrist3.stl"/>
      </geometry>
    </collision>
    <inertial>
      <mass value="0.1879"/>
      <origin rpy="0 0 0" xyz="0.0 0.0 0.0"/>
      <inertia ixx="0.0171364731454" ixy="0.0" ixz="0.0" iyy="0.0171364731454" iyz="0.0" izz="0.033822"/>
    </inertial>
  </link>


  <link name="tool0">
    <inertial>
      <mass value="0.0"/>
      <origin rpy="0 0 0" xyz="0.0 0.0 0.0"/>
      <inertia ixx="0.0" ixy="0.0" ixz="0.0" iyy="0.0" iyz="0.0" izz="0.0"/>
    </inertial>
  </link>>
  <joint name="wrist_3_link_tool0_joint" type="fixed">
    <parent link="wrist_3_link"/>
    <child link="tool0"/>
    <origin xyz="0 0.25 0" rpy="0 0 0"/>
  </joint>

  <!--################################################
  ########              gripper                  #####
  ####################################################-->

  <link name="hand_link">
      <collision>
          <origin xyz="0.00 0.00 0.00" rpy="0.00 0.00 0.00"/>
          <geometry>
              <mesh filename="../meshes/rg2_gripper/collision/RG2_Hand_col.STL"/>
          </geometry>
      </collision>
      <visual>
          <origin xyz="0.00 0.00 0.00" rpy="0.00 0.00 0.00"/>
          <geometry>
              <mesh filename="../meshes/rg2_gripper/visual/RG2_Hand_vis.STL"/>
          </geometry>
      </visual>
      <!-- <inertial>
          <origin xyz="0.058091 0.000192 -0.000016" rpy="0.00 0.00 0.00"/>
          <mass value="0.524520"/>
          <inertia ixx="0.000193" ixy="0.000000" ixz="0.000000"
                   iyy="0.000564" iyz="-0.000001"
                   izz="0.000636" />
      </inertial> -->
      <inertial>
          <origin xyz="0.061902 0.000129 -0.000005" rpy="0.00 0.00 0.00"/>
          <mass value="1.684558"/>
          <inertia ixx="0.000862" ixy="0.000000" ixz="0.000000"
                   iyy="0.002401" iyz="-0.000001"
                   izz="0.002620" />
      </inertial>
  </link>
  
  <joint name="l_finger_1_joint" type="revolute">
      <parent link="hand_link"/>
      <child link="l_moment_arm_link"/>
      <origin xyz="0.105 0.017 0.010" rpy="0 0 0"/>
      <axis xyz="0 0 1"/>
      <limit velocity="3.14" effort="10.6" lower="-0.45" upper="1.570796327" />
      <!-- <limit velocity="3.14" effort="100" lower="-3" upper="3" /> -->
      <!-- <dynamics damping="0.1" friction="0.0" /> -->
      <!-- <implicitSpringDamper>True</implicitSpringDamper> -->
  </joint>

  <link name="l_moment_arm_link">
      <collision>
          <origin xyz="0.00 0.00 0.00" rpy="0.00 0.00 0.00"/>
          <geometry>
              <mesh filename="../meshes/rg2_gripper/collision/RG2_LeftMomentArm_col.STL"/>
          </geometry>
      </collision>
      <visual>
          <origin xyz="0.00 0.00 0.00" rpy="0.00 0.00 0.00"/>
          <geometry>
              <mesh filename="../meshes/rg2_gripper/visual/RG2_LeftMomentArm_vis.STL"/>
          </geometry>
      </visual>
      <inertial>
          <origin xyz="0.017004 0.006397 -0.010300" rpy="0.00 0.00 0.00"/>
          <mass value="0.160209"/>
          <inertia ixx="0.000023" ixy="0.000019" ixz="0.000000"
                   iyy="0.000072" iyz="0.000000"
                   izz="0.000083" />
      </inertial>
  </link>
  <joint name="l_finger_2_joint" type="revolute">
      <parent link="l_moment_arm_link"/>
      <child link="l_finger_link"/>
      <origin xyz="0.049 0.026 0.000" rpy="0 0 0"/>
      <axis xyz="0 0 1"/>
      <limit velocity="3.14" effort="10.6" lower="-1.570796327" upper="1.570796327" />
      <!-- <limit velocity="3.14" effort="100" lower="-3" upper="3" /> -->
      <!-- <mimic joint="gripper_joint" multiplier="-1"/> -->
      <!-- <dynamics damping="0.1" friction="0.0" /> -->
      <!-- <implicitSpringDamper>True</implicitSpringDamper> -->
  </joint>
  <!-- <xacro:insert_transmission name="l_finger_2_joint" /> -->
  <!-- <xacro:mimic_joint_plugin_gazebo name_prefix="l_finger_2_joint"
                                   parent_joint="gripper_joint"
                                   mimic_joint="l_finger_2_joint"
                                   has_pid="false"
                                   multiplier="-1.0"
                                   max_effort="10.6" /> -->
  <link name="l_finger_link">
      <collision>
          <origin xyz="0.00 0.00 0.00" rpy="0.00 0.00 0.00"/>
          <geometry>
              <mesh filename="../meshes/rg2_gripper/collision/RG2_LeftFinger_col.STL"/>
          </geometry>
      </collision>
      <visual>
          <origin xyz="0.00 0.00 0.00" rpy="0.00 0.00 0.00"/>
          <geometry>
              <mesh filename="../meshes/rg2_gripper/visual/RG2_LeftFinger_vis.STL"/>
          </geometry>
      </visual>
      <inertial>
          <origin xyz="0.024695 -0.010178 -0.010001" rpy="0.00 0.00 0.00"/>
          <mass value="0.081638"/>
          <inertia ixx="0.000006" ixy="-0.000005" ixz="0.000000"
                   iyy="0.000025" iyz="0.000000"
                   izz="0.000026" />
      </inertial>
  </link>
  <joint name="l_finger_passive_joint" type="revolute">
      <parent link="hand_link"/>
      <child link="l_truss_arm_link"/>
      <origin xyz="0.122 0.008 0.010" rpy="0 0 0"/>
      <axis xyz="0 0 1"/>
      <limit velocity="3.14" effort="10.6" lower="-1.570796327" upper="1.570796327" />
      <!-- <limit velocity="3.14" effort="100" lower="-3" upper="3" /> -->
      <!-- <mimic joint="gripper_joint" multiplier="1"/> -->
      <!-- <dynamics damping="0.1" friction="0.0" /> -->
      <!-- <implicitSpringDamper>True</implicitSpringDamper> -->
  </joint>
  <!-- <xacro:insert_transmission name="l_finger_passive_joint" /> -->
  <xacro:mimic_joint_plugin_gazebo name_prefix="l_finger_passive_joint"
                                   parent_joint="gripper_joint"
                                   mimic_joint="l_finger_passive_joint"
                                   has_pid="false"
                                   multiplier="1.0"
                                   max_effort="10.6" />
  <link name="l_truss_arm_link">
      <collision>
          <origin xyz="0.00 0.00 0.00" rpy="0.00 0.00 0.00"/>
          <geometry>
              <mesh filename="../meshes/rg2_gripper/collision/RG2_LeftTrussArm_col.STL"/>
          </geometry>
      </collision>
      <visual>
          <origin xyz="0.00 0.00 0.00" rpy="0.00 0.00 0.00"/>
          <geometry>
              <mesh filename="../meshes/rg2_gripper/visual/RG2_LeftTrussArm_vis.STL"/>
          </geometry>
      </visual>
      <inertial>
          <origin xyz="0.023075 0.012136 -0.010000" rpy="0.00 0.00 0.00"/>
          <mass value="0.065927"/>
          <inertia ixx="0.000010" ixy="0.000010" ixz="0.000000"
                   iyy="0.000024" iyz="0.000000"
                   izz="0.000025" />
      </inertial>
  </link>
  <!-- Jari Kanan -->
  <joint name="r_finger_1_joint" type="revolute">
      <parent link="hand_link"/>
      <child link="r_moment_arm_link"/>
      <origin xyz="0.105 -0.017 0.010" rpy="0 0 0"/>
      <axis xyz="0 0 1"/>
      <limit velocity="3.14" effort="10.6" lower="-1.570796327" upper="1.570796327" />
      <!-- <limit velocity="3.14" effort="100" lower="-3" upper="3" /> -->
      <!-- <mimic joint="gripper_joint" multiplier="-1"/> -->
      <!-- <dynamics damping="0.1" friction="0.0" /> -->
      <!-- <implicitSpringDamper>True</implicitSpringDamper> -->
  </joint>
  <!-- <xacro:insert_transmission name="r_finger_1_joint" /> -->
 <!--  <xacro:mimic_joint_plugin_gazebo name_prefix="r_finger_1_joint"
                                   parent_joint="gripper_joint"
                                   mimic_joint="r_finger_1_joint"
                                   has_pid="false"
                                   multiplier="-1.0"
                                   max_effort="10.6" /> -->
  <link name="r_moment_arm_link">
      <collision>
          <origin xyz="0.00 0.00 0.00" rpy="0.00 0.00 0.00"/>
          <geometry>
              <mesh filename="../meshes/rg2_gripper/collision/RG2_RightMomentArm_col.STL"/>
          </geometry>
      </collision>
      <visual>
          <origin xyz="0.00 0.00 0.00" rpy="0.00 0.00 0.00"/>
          <geometry>
              <mesh filename="../meshes/rg2_gripper/visual/RG2_RightMomentArm_vis.STL"/>
          </geometry>
      </visual>
      <inertial>
          <origin xyz="0.017004 -0.006397 -0.010300" rpy="0.00 0.00 0.00"/>
          <mass value="0.160209"/>
          <inertia ixx="0.000023" ixy="-0.000019" ixz="0.000000"
                   iyy="0.000072" iyz="0.000000"
                   izz="0.000083" />
      </inertial>
  </link>
  <joint name="r_finger_2_joint" type="revolute">
      <parent link="r_moment_arm_link"/>
      <child link="r_finger_link"/>
      <origin xyz="0.049 -0.026 0.000" rpy="0 0 0"/>
      <axis xyz="0 0 1"/>
      <limit velocity="3.14" effort="10.6" lower="-1.570796327" upper="1.570796327" />
      <!-- <limit velocity="3.14" effort="100" lower="-3" upper="3" /> -->
      <!-- <mimic joint="gripper_joint" multiplier="1"/> -->
      <!-- <dynamics damping="0.1" friction="0.0" /> -->
      <!-- <implicitSpringDamper>True</implicitSpringDamper> -->
  </joint>
  <!-- <xacro:insert_transmission name="r_finger_2_joint" /> -->
  <!-- <xacro:mimic_joint_plugin_gazebo name_prefix="r_finger_2_joint"
                                   parent_joint="gripper_joint"
                                   mimic_joint="r_finger_2_joint"
                                   has_pid="false"
                                   multiplier="1.0"
                                   max_effort="10.6" /> -->
  <link name="r_finger_link">
      <collision>
          <origin xyz="0.00 0.00 0.00" rpy="0.00 0.00 0.00"/>
          <geometry>
              <mesh filename="../meshes/rg2_gripper/collision/RG2_RightFinger_col.STL"/>
          </geometry>
      </collision>
      <visual>
          <origin xyz="0.00 0.00 0.00" rpy="0.00 0.00 0.00"/>
          <geometry>
              <mesh filename="../meshes/rg2_gripper/visual/RG2_RightFinger_vis.STL"/>
          </geometry>
      </visual>
      <inertial>
          <origin xyz="0.024695 0.010178 -0.010000" rpy="0.00 0.00 0.00"/>
          <mass value="0.081637"/>
          <inertia ixx="0.000006" ixy="0.000005" ixz="0.000000"
                   iyy="0.000025" iyz="0.000000"
                   izz="0.000026" />
      </inertial>
  </link>
  <joint name="r_finger_passive_joint" type="revolute">
      <parent link="hand_link"/>
      <child link="r_truss_arm_link"/>
      <origin xyz="0.122 -0.008 0.010" rpy="0 0 0"/>
      <axis xyz="0 0 1"/>
      <limit velocity="3.14" effort="10.6" lower="-1.570796327" upper="1.570796327" />
      <!-- <limit velocity="3.14" effort="100" lower="-3" upper="3" /> -->
      <!-- <mimic joint="gripper_joint" multiplier="-1"/> -->
      <!-- <dynamics damping="0.1" friction="0.0" /> -->
      <!-- <implicitSpringDamper>True</implicitSpringDamper> -->
  </joint>
  <!-- <xacro:insert_transmission name="r_finger_passive_joint" /> -->
  <!-- <xacro:mimic_joint_plugin_gazebo name_prefix="r_finger_passive_joint"
                                   parent_joint="gripper_joint"
                                   mimic_joint="r_finger_passive_joint"
                                   has_pid="false"
                                   multiplier="-1.0"
                                   max_effort="10.6" /> -->
  <link name="r_truss_arm_link">
      <collision>
          <origin xyz="0.00 0.00 0.00" rpy="0.00 0.00 0.00"/>
          <geometry>
              <mesh filename="../meshes/rg2_gripper/collision/RG2_RightTrussArm_col.STL"/>
          </geometry>
      </collision>
      <visual>
          <origin xyz="0.00 0.00 0.00" rpy="0.00 0.00 0.00"/>
          <geometry>
              <mesh filename="../meshes/rg2_gripper/visual/RG2_RightTrussArm_vis.STL"/>
          </geometry>
      </visual>
      <inertial>
          <origin xyz="0.023075 -0.012136 -0.010000" rpy="0.00 0.00 0.00"/>
          <mass value="0.065927"/>
          <inertia ixx="0.000010" ixy="-0.000010" ixz="0.000000"
                   iyy="0.000024" iyz="0.000000"
                   izz="0.000025" />
      </inertial>
  </link>


  

  <!--################################################
  ########          connect model                #####
  ####################################################-->

  <!-- connect arm to world -->
  <link name="world"/>
  <joint name="world_joint" type="fixed">
    <parent link="world"/>
    <child link="base_link"/>
    <origin rpy="0.0 0.0 0.0" xyz="0.0 0.0 0.0"/>
  </joint>

  <!-- connect gripper to arm -->
  <joint name="arm_gripper_joint" type="fixed">
    <parent link="wrist_3_link"/>
    <child link="hand_link"/>
    <origin rpy="0.0 0.0 1.57" xyz="0.0 0.085 0.0"/>
  </joint>

</robot>


